Workbook

Sheet Start Here
A1: Cafe Carolina (TEST) - recipe costing
A3: Right now Clerque cannot tell you what a plate of wings costs, and it is not because anything is broken. Two things are genuinely not written down anywhere.
A5: First, 18 ingredients have no price at all - the soy sauce, the honey, the butter, the salt. A dish made of those is costed as if it were free.
A6: Second, nobody has ever measured how much sauce comes out of a pot. Without that, there is no way to know what a spoonful costs, however carefully everything else is counted.
A8: There are four questions, and a cook can answer all of them
A9: 1. What does one pack of each ingredient cost? -> the "Ingredients" tab
A10: 2. What goes into ONE POT of each sauce? -> the "Sauce Batches" tab
A11: 3. How much comes OUT of that pot? -> the "Sauce Batches" tab
A12: 4. How much sauce goes on ONE PLATE? -> the "On the Plate" tab
A14: Nobody is asked how many servings a pot makes. That is question 3 divided by question 4, and the "Answers" tab works it out.
A16: How to fill it in
A17: Only the shaded cells need anything. Everything else is either what Clerque already holds, or a number that works itself out as you type.
... A39: Generated from carolina-test - 361 ingredients, 7 dishes, 1 existing preps.

Sheet Ingredients
A1: What these cost - Cafe Carolina (TEST)
A2: These 18 ingredients have no price in Clerque, so every dish that uses one is costed as if it were free. Nothing else in this file works until they are filled in.
A3: Write the price of ONE of whatever you BUY - one kilo, one bottle, one pack. Do not divide it down yourself; the last column does that. If you buy it in a container (a pack, a bottle, a can), also say how many grams or millilitres are inside one, under Pack Size.
A4: Only the shaded cells are yours. The name and the Recipe Unit are what Clerque already holds - changing either one would create a second copy of the ingredient.
A6: Name* | B6: Unit* | C6: Cost per Unit (₱)* | D6: Low Stock Alert | E6: Notes | F6: Recipe Unit | G6: Pack Size | H6: Category | I6: What that works out to (₱ per recipe unit) | J6: Check
A7: Required. Unique within tenant. | B7: Required. How you BUY it: L / kg / carton / pc / bottle. | C7: REQUIRED. Price of ONE of the unit above. Do not pre-divide. | D7: Optional. Stock-low threshold, in Recipe Units. | E7: Optional. Free text. | F7: Optional. How a RECIPE uses it: ml / g / pc. Blank = same as Unit. | G7: Only for containers. How many Recipe Units in one Unit. | H7: Optional. Ingredient / Kitchen Supply / Bar Supply / Office Supply. Blank = Ingredient. | I7: Worked out for you. Leave this one alone. | J7: Speaks up if a price looks like it belongs to a different size.
A8: Apple cider vinegar | E8: Used in: Herbed Honey Garlic | F8: g | I8: =IF($C8="","",IF(NOT(ISNUMBER($C8)),"Type just the number",IF($B8="","Which unit do you buy it in?",IF(EXACT(LOWER($B8),LOWER($F8)),$C8,IF(IFERROR(VLOOKUP(LOWER($B8),Lists!$E:$G,2,FALSE),"?buy")=IFERROR(VLOOKUP(LOWER($F8),Lists!$E:$G,2,FALSE),"?rec"),IF($G8<>"","Leave Pack Size blank",$C8/(VLOOKUP(LOWER($B8),Lists!$E:$G,3,FALSE)/VLOOKUP(LOWER($F8),Lists!$E:$G,3,FALSE))),IF(AND(ISNUMBER($G8),$G8>0),$C8/$G8,"How many "&$F8&" in one "&$B8&"?")))))) | J8: =IF(NOT(ISNUMBER($C8)),"",IF(AND(OR(EXACT(LOWER($B8),"g"),EXACT(LOWER($B8),"ml")),$C8>20),"That is ₱"&TEXT($C8,"0.00")&" for ONE "&$B8&". Did you mean one kilo, or one litre?",""))
A9: Butter | E9: Used in: Buffalo Wings, Garlic Chicken, Garlic Parmesan, Herbed Honey Garlic, Teriyaki Wings | F9: g | I9: =IF($C9="","",IF(NOT(ISNUMBER($C9)),"Type just the number",IF($B9="","Which unit do you buy it in?",IF(EXACT(LOWER($B9),LOWER($F9)),$C9,IF(IFERROR(VLOOKUP(LOWER($B9),Lists!$E:$G,2,FALSE),"?buy")=IFERROR(VLOOKUP(LOWER($F9),Lists!$E:$G,2,FALSE),"?rec"),IF($G9<>"","Leave Pack Size blank",$C9/(VLOOKUP(LOWER($B9),Lists!$E:$G,3,FALSE)/VLOOKUP(LOWER($F9),Lists!$E:$G,3,FALSE))),IF(AND(ISNUMBER($G9),$G9>0),$C9/$G9,"How many "&$F9&" in one "&$B9&"?")))))) | J9: =IF(NOT(ISNUMBER($C9)),"",IF(AND(OR(EXACT(LOWER($B9),"g"),EXACT(LOWER($B9),"ml")),$C9>20),"That is ₱"&TEXT($C9,"0.00")&" for ONE "&$B9&". Did you mean one kilo, or one litre?",""))
A10: Cayenne pepper | E10: Used in: Buffalo Wings | F10: g | I10: =IF($C10="","",IF(NOT(ISNUMBER($C10)),"Type just the number",IF($B10="","Which unit do you buy it in?",IF(EXACT(LOWER($B10),LOWER($F10)),$C10,IF(IFERROR(VLOOKUP(LOWER($B10),Lists!$E:$G,2,FALSE),"?buy")=IFERROR(VLOOKUP(LOWER($F10),Lists!$E:$G,2,FALSE),"?rec"),IF($G10<>"","Leave Pack Size blank",$C10/(VLOOKUP(LOWER($B10),Lists!$E:$G,3,FALSE)/VLOOKUP(LOWER($F10),Lists!$E:$G,3,FALSE))),IF(AND(ISNUMBER($G10),$G10>0),$C10/$G10,"How many "&$F10&" in one "&$B10&"?")))))) | J10: =IF(NOT(ISNUMBER($C10)),"",IF(AND(OR(EXACT(LOWER($B10),"g"),EXACT(LOWER($B10),"ml")),$C10>20),"That is ₱"&TEXT($C10,"0.00")&" for ONE "&$B10&". Did you mean one kilo, or one litre?",""))
A11: Dried rosemary | E11: Used in: Herbed Honey Garlic | F11: g | I11: =IF($C11="","",IF(NOT(ISNUMBER($C11)),"Type just the number",IF($B11="","Which unit do you buy it in?",IF(EXACT(LOWER($B11),LOWER($F11)),$C11,IF(IFERROR(VLOOKUP(LOWER($B11),Lists!$E:$G,2,FALSE),"?buy")=IFERROR(VLOOKUP(LOWER($F11),Lists!$E:$G,2,FALSE),"?rec"),IF($G11<>"","Leave Pack Size blank",$C11/(VLOOKUP(LOWER($B11),Lists!$E:$G,3,FALSE)/VLOOKUP(LOWER($F11),Lists!$E:$G,3,FALSE))),IF(AND(ISNUMBER($G11),$G11>0),$C11/$G11,"How many "&$F11&" in one "&$B11&"?")))))) | J11: =IF(NOT(ISNUMBER($C11)),"",IF(AND(OR(EXACT(LOWER($B11),"g"),EXACT(LOWER($B11),"ml")),$C11>20),"That is ₱"&TEXT($C11,"0.00")&" for ONE "&$B11&". Did you mean one kilo, or one litre?",""))
A12: Dried thyme | E12: Used in: Herbed Honey Garlic | F12: g | I12: =IF($C12="","",IF(NOT(ISNUMBER($C12)),"Type just the number",IF($B12="","Which unit do you buy it in?",IF(EXACT(LOWER($B12),LOWER($F12)),$C12,IF(IFERROR(VLOOKUP(LOWER($B12),Lists!$E:$G,2,FALSE),"?buy")=IFERROR(VLOOKUP(LOWER($F12),Lists!$E:$G,2,FALSE),"?rec"),IF($G12<>"","Leave Pack Size blank",$C12/(VLOOKUP(LOWER($B12),Lists!$E:$G,3,FALSE)/VLOOKUP(LOWER($F12),Lists!$E:$G,3,FALSE))),IF(AND(ISNUMBER($G12),$G12>0),$C12/$G12,"How many "&$F12&" in one "&$B12&"?")))))) | J12: =IF(NOT(ISNUMBER($C12)),"",IF(AND(OR(EXACT(LOWER($B12),"g"),EXACT(LOWER($B12),"ml")),$C12>20),"That is ₱"&TEXT($C12,"0.00")&" for ONE "&$B12&". Did you mean one kilo, or one litre?",""))
A13: Flour | E13: Used in: Buffalo Wings, Herbed Honey Garlic | F13: g | I13: =IF($C13="","",IF(NOT(ISNUMBER($C13)),"Type just the number",IF($B13="","Which unit do you buy it in?",IF(EXACT(LOWER($B13),LOWER($F13)),$C13,IF(IFERROR(VLOOKUP(LOWER($B13),Lists!$E:$G,2,FALSE),"?buy")=IFERROR(VLOOKUP(LOWER($F13),Lists!$E:$G,2,FALSE),"?rec"),IF($G13<>"","Leave Pack Size blank",$C13/(VLOOKUP(LOWER($B13),Lists!$E:$G,3,FALSE)/VLOOKUP(LOWER($F13),Lists!$E:$G,3,FALSE))),IF(AND(ISNUMBER($G13),$G13>0),$C13/$G13,"How many "&$F13&" in one "&$B13&"?")))))) | J13: =IF(NOT(ISNUMBER($C13)),"",IF(AND(OR(EXACT(LOWER($B13),"g"),EXACT(LOWER($B13),"ml")),$C13>20),"That is ₱"&TEXT($C13,"0.00")&" for ONE "&$B13&". Did you mean one kilo, or one litre?",""))
A14: Garlic powder | E14: Used in: Sweet & Spicy BBQ, Teriyaki Wings, Teriyaki Sauce (frozen) | F14: g | I14: =IF($C14="","",IF(NOT(ISNUMBER($C14)),"Type just the number",IF($B14="","Which unit do you buy it in?",IF(EXACT(LOWER($B14),LOWER($F14)),$C14,IF(IFERROR(VLOOKUP(LOWER($B14),Lists!$E:$G,2,FALSE),"?buy")=IFERROR(VLOOKUP(LOWER($F14),Lists!$E:$G,2,FALSE),"?rec"),IF($G14<>"","Leave Pack Size blank",$C14/(VLOOKUP(LOWER($B14),Lists!$E:$G,3,FALSE)/VLOOKUP(LOWER($F14),Lists!$E:$G,3,FALSE))),IF(AND(ISNUMBER($G14),$G14>0),$C14/$G14,"How many "&$F14&" in one "&$B14&"?")))))) | J14: =IF(NOT(ISNUMBER($C14)),"",IF(AND(OR(EXACT(LOWER($B14),"g"),EXACT(LOWER($B14),"ml")),$C14>20),"That is ₱"&TEXT($C14,"0.00")&" for ONE "&$B14&". Did you mean one kilo, or one litre?",""))
A15: Ginger | E15: Used in: Teriyaki Wings, Teriyaki Sauce (frozen) | F15: g | I15: =IF($C15="","",IF(NOT(ISNUMBER($C15)),"Type just the number",IF($B15="","Which unit do you buy it in?",IF(EXACT(LOWER($B15),LOWER($F15)),$C15,IF(IFERROR(VLOOKUP(LOWER($B15),Lists!$E:$G,2,FALSE),"?buy")=IFERROR(VLOOKUP(LOWER($F15),Lists!$E:$G,2,FALSE),"?rec"),IF($G15<>"","Leave Pack Size blank",$C15/(VLOOKUP(LOWER($B15),Lists!$E:$G,3,FALSE)/VLOOKUP(LOWER($F15),Lists!$E:$G,3,FALSE))),IF(AND(ISNUMBER($G15),$G15>0),$C15/$G15,"How many "&$F15&" in one "&$B15&"?")))))) | J15: =IF(NOT(ISNUMBER($C15)),"",IF(AND(OR(EXACT(LOWER($B15),"g"),EXACT(LOWER($B15),"ml")),$C15>20),"That is ₱"&TEXT($C15,"0.00")&" for ONE "&$B15&". Did you mean one kilo, or one litre?",""))
A16: Honey | E16: Used in: Garlic Parmesan, Herbed Honey Garlic, Honey Sriracha | F16: g | I16: =IF($C16="","",IF(NOT(ISNUMBER($C16)),"Type just the number",IF($B16="","Which unit do you buy it in?",IF(EXACT(LOWER($B16),LOWER($F16)),$C16,IF(IFERROR(VLOOKUP(LOWER($B16),Lists!$E:$G,2,FALSE),"?buy")=IFERROR(VLOOKUP(LOWER($F16),Lists!$E:$G,2,FALSE),"?rec"),IF($G16<>"","Leave Pack Size blank",$C16/(VLOOKUP(LOWER($B16),Lists!$E:$G,3,FALSE)/VLOOKUP(LOWER($F16),Lists!$E:$G,3,FALSE))),IF(AND(ISNUMBER($G16),$G16>0),$C16/$G16,"How many "&$F16&" in one "&$B16&"?")))))) | J16: =IF(NOT(ISNUMBER($C16)),"",IF(AND(OR(EXACT(LOWER($B16),"g"),EXACT(LOWER($B16),"ml")),$C16>20),"That is ₱"&TEXT($C16,"0.00")&" for ONE "&$B16&". Did you mean one kilo, or one litre?",""))
A17: Ketchup | E17: Used in: Sweet & Spicy BBQ | F17: g | I17: =IF($C17="","",IF(NOT(ISNUMBER($C17)),"Type just the number",IF($B17="","Which unit do you buy it in?",IF(EXACT(LOWER($B17),LOWER($F17)),$C17,IF(IFERROR(VLOOKUP(LOWER($B17),Lists!$E:$G,2,FALSE),"?buy")=IFERROR(VLOOKUP(LOWER($F17),Lists!$E:$G,2,FALSE),"?rec"),IF($G17<>"","Leave Pack Size blank",$C17/(VLOOKUP(LOWER($B17),Lists!$E:$G,3,FALSE)/VLOOKUP(LOWER($F17),Lists!$E:$G,3,FALSE))),IF(AND(ISNUMBER($G17),$G17>0),$C17/$G17,"How many "&$F17&" in one "&$B17&"?")))))) | J17: =IF(NOT(ISNUMBER($C17)),"",IF(AND(OR(EXACT(LOWER($B17),"g"),EXACT(LOWER($B17),"ml")),$C17>20),"That is ₱"&TEXT($C17,"0.00")&" for ONE "&$B17&". Did you mean one kilo, or one litre?",""))
A18: Oil | E18: Used in: Sweet & Spicy BBQ | F18: g | I18: =IF($C18="","",IF(NOT(ISNUMBER($C18)),"Type just the number",IF($B18="","Which unit do you buy it in?",IF(EXACT(LOWER($B18),LOWER($F18)),$C18,IF(IFERROR(VLOOKUP(LOWER($B18),Lists!$E:$G,2,FALSE),"?buy")=IFERROR(VLOOKUP(LOWER($F18),Lists!$E:$G,2,FALSE),"?rec"),IF($G18<>"","Leave Pack Size blank",$C18/(VLOOKUP(LOWER($B18),Lists!$E:$G,3,FALSE)/VLOOKUP(LOWER($F18),Lists!$E:$G,3,FALSE))),IF(AND(ISNUMBER($G18),$G18>0),$C18/$G18,"How many "&$F18&" in one "&$B18&"?")))))) | J18: =IF(NOT(ISNUMBER($C18)),"",IF(AND(OR(EXACT(LOWER($B18),"g"),EXACT(LOWER($B18),"ml")),$C18>20),"That is ₱"&TEXT($C18,"0.00")&" for ONE "&$B18&". Did you mean one kilo, or one litre?",""))
A19: Paprika | E19: Used in: Buffalo Wings | F19: g | I19: =IF($C19="","",IF(NOT(ISNUMBER($C19)),"Type just the number",IF($B19="","Which unit do you buy it in?",IF(EXACT(LOWER($B19),LOWER($F19)),$C19,IF(IFERROR(VLOOKUP(LOWER($B19),Lists!$E:$G,2,FALSE),"?buy")=IFERROR(VLOOKUP(LOWER($F19),Lists!$E:$G,2,FALSE),"?rec"),IF($G19<>"","Leave Pack Size blank",$C19/(VLOOKUP(LOWER($B19),Lists!$E:$G,3,FALSE)/VLOOKUP(LOWER($F19),Lists!$E:$G,3,FALSE))),IF(AND(ISNUMBER($G19),$G19>0),$C19/$G19,"How many "&$F19&" in one "&$B19&"?")))))) | J19: =IF(NOT(ISNUMBER($C19)),"",IF(AND(OR(EXACT(LOWER($B19),"g"),EXACT(LOWER($B19),"ml")),$C19>20),"That is ₱"&TEXT($C19,"0.00")&" for ONE "&$B19&". Did you mean one kilo, or one litre?",""))
... A25: Sriracha | E25: Used in: Buffalo Wings, Honey Sriracha, Sweet & Spicy BBQ | F25: g | I25: =IF($C25="","",IF(NOT(ISNUMBER($C25)),"Type just the number",IF($B25="","Which unit do you buy it in?",IF(EXACT(LOWER($B25),LOWER($F25)),$C25,IF(IFERROR(VLOOKUP(LOWER($B25),Lists!$E:$G,2,FALSE),"?buy")=IFERROR(VLOOKUP(LOWER($F25),Lists!$E:$G,2,FALSE),"?rec"),IF($G25<>"","Leave Pack Size blank",$C25/(VLOOKUP(LOWER($B25),Lists!$E:$G,3,FALSE)/VLOOKUP(LOWER($F25),Lists!$E:$G,3,FALSE))),IF(AND(ISNUMBER($G25),$G25>0),$C25/$G25,"How many "&$F25&" in one "&$B25&"?")))))) | J25: =IF(NOT(ISNUMBER($C25)),"",IF(AND(OR(EXACT(LOWER($B25),"g"),EXACT(LOWER($B25),"ml")),$C25>20),"That is ₱"&TEXT($C25,"0.00")&" for ONE "&$B25&". Did you mean one kilo, or one litre?",""))

Sheet Sauce Batches
A1: One pot at a time - Cafe Carolina (TEST)
A2: For each sauce: write what goes into ONE POT, then weigh or measure what comes out. That second number is the one nobody has, and it is the one that decides what the sauce costs - cost per millilitre is simply what went in, divided by what came out.
A3: You only have to measure the pot ONCE. If the next pot comes out different, tell us and we will change it.
A5: PREP: Teriyaki Sauce (frozen)
A6: Clerque already holds this as a prep, assuming one batch makes 2,000 ml - nobody has checked that number against a jug.
A7: Ingredient | B7: Unit | C7: Your recipe today (per pot) | D7: Goes into ONE POT | E7: ₱ this costs
A8: Soy sauce | B8: =IF($A8="","",IFERROR(VLOOKUP($A8,Lists!$A:$C,3,FALSE),"NOT ON THE LIST")) -> g | C8: 600 | E8: =IF(OR($A8="",NOT(ISNUMBER($D8))),"",IFERROR($D8*VLOOKUP($A8,Lists!$A:$B,2,FALSE),""))
A9: Sugar | B9: =IF($A9="","",IFERROR(VLOOKUP($A9,Lists!$A:$C,3,FALSE),"NOT ON THE LIST")) -> g | C9: 760 | E9: =IF(OR($A9="",NOT(ISNUMBER($D9))),"",IFERROR($D9*VLOOKUP($A9,Lists!$A:$B,2,FALSE),""))
A10: Ginger | B10: =IF($A10="","",IFERROR(VLOOKUP($A10,Lists!$A:$C,3,FALSE),"NOT ON THE LIST")) -> g | C10: 8 | E10: =IF(OR($A10="",NOT(ISNUMBER($D10))),"",IFERROR($D10*VLOOKUP($A10,Lists!$A:$B,2,FALSE),""))
A11: Garlic powder | B11: =IF($A11="","",IFERROR(VLOOKUP($A11,Lists!$A:$C,3,FALSE),"NOT ON THE LIST")) -> g | C11: 10 | E11: =IF(OR($A11="",NOT(ISNUMBER($D11))),"",IFERROR($D11*VLOOKUP($A11,Lists!$A:$B,2,FALSE),""))
A12: Chicken powder | B12: =IF($A12="","",IFERROR(VLOOKUP($A12,Lists!$A:$C,3,FALSE),"NOT ON THE LIST")) -> g | C12: 80 | E12: =IF(OR($A12="",NOT(ISNUMBER($D12))),"",IFERROR($D12*VLOOKUP($A12,Lists!$A:$B,2,FALSE),""))
A13: Water | B13: =IF($A13="","",IFERROR(VLOOKUP($A13,Lists!$A:$C,3,FALSE),"NOT ON THE LIST")) -> ml | C13: 400 | E13: =IF(OR($A13="",NOT(ISNUMBER($D13))),"",IFERROR($D13*VLOOKUP($A13,Lists!$A:$B,2,FALSE),""))
B14: =IF($A14="","",IFERROR(VLOOKUP($A14,Lists!$A:$C,3,FALSE),"NOT ON THE LIST")) | E14: =IF(OR($A14="",NOT(ISNUMBER($D14))),"",IFERROR($D14*VLOOKUP($A14,Lists!$A:$B,2,FALSE),""))
B15: =IF($A15="","",IFERROR(VLOOKUP($A15,Lists!$A:$C,3,FALSE),"NOT ON THE LIST")) | E15: =IF(OR($A15="",NOT(ISNUMBER($D15))),"",IFERROR($D15*VLOOKUP($A15,Lists!$A:$B,2,FALSE),""))
B16: =IF($A16="","",IFERROR(VLOOKUP($A16,Lists!$A:$C,3,FALSE),"NOT ON THE LIST")) | E16: =IF(OR($A16="",NOT(ISNUMBER($D16))),"",IFERROR($D16*VLOOKUP($A16,Lists!$A:$B,2,FALSE),""))
B17: =IF($A17="","",IFERROR(VLOOKUP($A17,Lists!$A:$C,3,FALSE),"NOT ON THE LIST")) | E17: =IF(OR($A17="",NOT(ISNUMBER($D17))),"",IFERROR($D17*VLOOKUP($A17,Lists!$A:$B,2,FALSE),""))
B18: =IF($A18="","",IFERROR(VLOOKUP($A18,Lists!$A:$C,3,FALSE),"NOT ON THE LIST")) | E18: =IF(OR($A18="",NOT(ISNUMBER($D18))),"",IFERROR($D18*VLOOKUP($A18,Lists!$A:$B,2,FALSE),""))
B19: =IF($A19="","",IFERROR(VLOOKUP($A19,Lists!$A:$C,3,FALSE),"NOT ON THE LIST")) | E19: =IF(OR($A19="",NOT(ISNUMBER($D19))),"",IFERROR($D19*VLOOKUP($A19,Lists!$A:$B,2,FALSE),""))
A20: TOTAL that goes into the pot | E20: =SUM($E$8:$E$19) -> 0
A21: How much comes OUT of the pot <- measure this once | B21: ml
A22: So ONE unit of this sauce costs | E22: =IF(OR(NOT(ISNUMBER($D$21)),$D$21<=0),"",$E$20/$D$21)
A24: SAUCE FOR: Buffalo Wings
A25: The amounts below are what the recipe says goes on ONE PLATE. Write the POT amounts beside them. Leave the pot column blank for anything that is not part of the sauce, like the chicken itself.
A26: Ingredient | B26: Unit | C26: Your recipe today (per plate) | D26: Goes into ONE POT | E26: ₱ this costs
A27: Butter | B27: =IF($A27="","",IFERROR(VLOOKUP($A27,Lists!$A:$C,3,FALSE),"NOT ON THE LIST")) -> g | C27: 0.7 | E27: =IF(OR($A27="",NOT(ISNUMBER($D27))),"",IFERROR($D27*VLOOKUP($A27,Lists!$A:$B,2,FALSE),""))
A28: Cayenne pepper | B28: =IF($A28="","",IFERROR(VLOOKUP($A28,Lists!$A:$C,3,FALSE),"NOT ON THE LIST")) -> g | C28: 1 | E28: =IF(OR($A28="",NOT(ISNUMBER($D28))),"",IFERROR($D28*VLOOKUP($A28,Lists!$A:$B,2,FALSE),""))
A29: Chili powder | B29: =IF($A29="","",IFERROR(VLOOKUP($A29,Lists!$A:$C,3,FALSE),"NOT ON THE LIST")) -> g | C29: 1 | E29: =IF(OR($A29="",NOT(ISNUMBER($D29))),"",IFERROR($D29*VLOOKUP($A29,Lists!$A:$B,2,FALSE),""))
A30: Flour | B30: =IF($A30="","",IFERROR(VLOOKUP($A30,Lists!$A:$C,3,FALSE),"NOT ON THE LIST")) -> g | C30: 20 | E30: =IF(OR($A30="",NOT(ISNUMBER($D30))),"",IFERROR($D30*VLOOKUP($A30,Lists!$A:$B,2,FALSE),""))
A31: Ground Black Pepper | B31: =IF($A31="","",IFERROR(VLOOKUP($A31,Lists!$A:$C,3,FALSE),"NOT ON THE LIST")) -> g | C31: 1 | E31: =IF(OR($A31="",NOT(ISNUMBER($D31))),"",IFERROR($D31*VLOOKUP($A31,Lists!$A:$B,2,FALSE),""))
A32: Paprika | B32: =IF($A32="","",IFERROR(VLOOKUP($A32,Lists!$A:$C,3,FALSE),"NOT ON THE LIST")) -> g | C32: 1 | E32: =IF(OR($A32="",NOT(ISNUMBER($D32))),"",IFERROR($D32*VLOOKUP($A32,Lists!$A:$B,2,FALSE),""))
A33: Salt | B33: =IF($A33="","",IFERROR(VLOOKUP($A33,Lists!$A:$C,3,FALSE),"NOT ON THE LIST")) -> g | C33: 0.8 | E33: =IF(OR($A33="",NOT(ISNUMBER($D33))),"",IFERROR($D33*VLOOKUP($A33,Lists!$A:$B,2,FALSE),""))
A34: Sesame Seed | B34: =IF($A34="","",IFERROR(VLOOKUP($A34,Lists!$A:$C,3,FALSE),"NOT ON THE LIST")) -> g | C34: 5 | E34: =IF(OR($A34="",NOT(ISNUMBER($D34))),"",IFERROR($D34*VLOOKUP($A34,Lists!$A:$B,2,FALSE),""))
A35: Sriracha | B35: =IF($A35="","",IFERROR(VLOOKUP($A35,Lists!$A:$C,3,FALSE),"NOT ON THE LIST")) -> g | C35: 15 | E35: =IF(OR($A35="",NOT(ISNUMBER($D35))),"",IFERROR($D35*VLOOKUP($A35,Lists!$A:$B,2,FALSE),""))
A36: Sugar | B36: =IF($A36="","",IFERROR(VLOOKUP($A36,Lists!$A:$C,3,FALSE),"NOT ON THE LIST")) -> g | C36: 5 | E36: =IF(OR($A36="",NOT(ISNUMBER($D36))),"",IFERROR($D36*VLOOKUP($A36,Lists!$A:$B,2,FALSE),""))
B37: =IF($A37="","",IFERROR(VLOOKUP($A37,Lists!$A:$C,3,FALSE),"NOT ON THE LIST")) | E37: =IF(OR($A37="",NOT(ISNUMBER($D37))),"",IFERROR($D37*VLOOKUP($A37,Lists!$A:$B,2,FALSE),""))
B38: =IF($A38="","",IFERROR(VLOOKUP($A38,Lists!$A:$C,3,FALSE),"NOT ON THE LIST")) | E38: =IF(OR($A38="",NOT(ISNUMBER($D38))),"",IFERROR($D38*VLOOKUP($A38,Lists!$A:$B,2,FALSE),""))
B39: =IF($A39="","",IFERROR(VLOOKUP($A39,Lists!$A:$C,3,FALSE),"NOT ON THE LIST")) | E39: =IF(OR($A39="",NOT(ISNUMBER($D39))),"",IFERROR($D39*VLOOKUP($A39,Lists!$A:$B,2,FALSE),""))
B40: =IF($A40="","",IFERROR(VLOOKUP($A40,Lists!$A:$C,3,FALSE),"NOT ON THE LIST")) | E40: =IF(OR($A40="",NOT(ISNUMBER($D40))),"",IFERROR($D40*VLOOKUP($A40,Lists!$A:$B,2,FALSE),""))
B41: =IF($A41="","",IFERROR(VLOOKUP($A41,Lists!$A:$C,3,FALSE),"NOT ON THE LIST")) | E41: =IF(OR($A41="",NOT(ISNUMBER($D41))),"",IFERROR($D41*VLOOKUP($A41,Lists!$A:$B,2,FALSE),""))
B42: =IF($A42="","",IFERROR(VLOOKUP($A42,Lists!$A:$C,3,FALSE),"NOT ON THE LIST")) | E42: =IF(OR($A42="",NOT(ISNUMBER($D42))),"",IFERROR($D42*VLOOKUP($A42,Lists!$A:$B,2,FALSE),""))
...

Sheet On the Plate
A1: What one plate costs - Cafe Carolina (TEST)
A2: Two numbers per dish: how much sauce goes on one plate, and how much chicken. Everything to the right of them works itself out - including how many plates one pot makes, which is why nobody is asked to count servings.
A3: If measuring a ladle is awkward, answer the other one instead: how many plates does ONE POT do? Ilang plato ang kaya ng isang kaldero? Either answer gives the same result, and you only need one of the two.
A4: The main item is whatever the plate is actually made of. Five of these dishes have no chicken in the recipe at all today, which is why they look almost free to make.
A6: Dish | B6: Sells for ₱ | C6: Sauce on one plate | D6: unit | E6: ...or plates from one pot | F6: → sauce per plate used | G6: Main item (the meat) | H6: How much on one plate | I6: unit | J6: → sauce costs | K6: → main item costs | L6: → COST PER PLATE | M6: → you keep | N6: → margin | O6: → plates per pot | P6: Check
B7: What it sells for now. | C7: Ilang gramo o ml sa isang plato? Measure the ladle once. | E7: Ilang plato ang kaya ng isang kaldero? Answer this OR the one on the left. | F7: Whichever of the two you answered. | G7: Pick from the list. | H7: Grams, or pieces - whatever the unit says. | O7: Worked out for you. | P7: Speaks up if the same thing is counted twice.
A8: Buffalo Wings | B8: 150 | D8: =IF('Sauce Batches'!$B$44="","",'Sauce Batches'!$B$44) | F8: =IF(ISNUMBER($C8),$C8,IF(AND(ISNUMBER($E8),$E8>0,ISNUMBER('Sauce Batches'!$D$44)),'Sauce Batches'!$D$44/$E8,"")) | G8: Chicken wings | H8: 2 | I8: =IF($G8="","",IFERROR(VLOOKUP($G8,Lists!$A:$C,3,FALSE),"NOT ON THE LIST")) -> pc | J8: =IF(OR(NOT(ISNUMBER($F8)),NOT(ISNUMBER('Sauce Batches'!$E$45))),"",$F8*'Sauce Batches'!$E$45) | K8: =IF(OR($G8="",NOT(ISNUMBER($H8))),"",IFERROR($H8*VLOOKUP($G8,Lists!$A:$B,2,FALSE),"")) -> 22.0252 | L8: =IF(AND($J8="",$K8=""),"",N($J8)+N($K8)) -> 22.03 | M8: =IF($L8="","",$B8-$L8) -> 127.97 | N8: =IF(OR($L8="",$B8=0),"",($B8-$L8)/$B8) -> 0.85316533 | O8: =IF(OR(NOT(ISNUMBER($F8)),$F8<=0,NOT(ISNUMBER('Sauce Batches'!$D$44))),"",'Sauce Batches'!$D$44/$F8) | P8: =IF($G8="","",IF(SUMPRODUCT(('Sauce Batches'!$A$27:$A$42=$G8)*(ISNUMBER('Sauce Batches'!$D$27:$D$42)))>0,"This is also in the pot above - it would be paid for twice",""))
A9: Garlic Chicken | B9: 150 | D9: =IF('Sauce Batches'!$B$61="","",'Sauce Batches'!$B$61) | F9: =IF(ISNUMBER($C9),$C9,IF(AND(ISNUMBER($E9),$E9>0,ISNUMBER('Sauce Batches'!$D$61)),'Sauce Batches'!$D$61/$E9,"")) | I9: =IF($G9="","",IFERROR(VLOOKUP($G9,Lists!$A:$C,3,FALSE),"NOT ON THE LIST")) | J9: =IF(OR(NOT(ISNUMBER($F9)),NOT(ISNUMBER('Sauce Batches'!$E$62))),"",$F9*'Sauce Batches'!$E$62) | K9: =IF(OR($G9="",NOT(ISNUMBER($H9))),"",IFERROR($H9*VLOOKUP($G9,Lists!$A:$B,2,FALSE),"")) | L9: =IF(AND($J9="",$K9=""),"",N($J9)+N($K9)) | M9: =IF($L9="","",$B9-$L9) | N9: =IF(OR($L9="",$B9=0),"",($B9-$L9)/$B9) | O9: =IF(OR(NOT(ISNUMBER($F9)),$F9<=0,NOT(ISNUMBER('Sauce Batches'!$D$61))),"",'Sauce Batches'!$D$61/$F9) | P9: =IF($G9="","",IF(SUMPRODUCT(('Sauce Batches'!$A$50:$A$59=$G9)*(ISNUMBER('Sauce Batches'!$D$50:$D$59)))>0,"This is also in the pot above - it would be paid for twice",""))
A10: Garlic Parmesan | B10: 150 | D10: =IF('Sauce Batches'!$B$80="","",'Sauce Batches'!$B$80) | F10: =IF(ISNUMBER($C10),$C10,IF(AND(ISNUMBER($E10),$E10>0,ISNUMBER('Sauce Batches'!$D$80)),'Sauce Batches'!$D$80/$E10,"")) | I10: =IF($G10="","",IFERROR(VLOOKUP($G10,Lists!$A:$C,3,FALSE),"NOT ON THE LIST")) | J10: =IF(OR(NOT(ISNUMBER($F10)),NOT(ISNUMBER('Sauce Batches'!$E$81))),"",$F10*'Sauce Batches'!$E$81) | K10: =IF(OR($G10="",NOT(ISNUMBER($H10))),"",IFERROR($H10*VLOOKUP($G10,Lists!$A:$B,2,FALSE),"")) | L10: =IF(AND($J10="",$K10=""),"",N($J10)+N($K10)) | M10: =IF($L10="","",$B10-$L10) | N10: =IF(OR($L10="",$B10=0),"",($B10-$L10)/$B10) | O10: =IF(OR(NOT(ISNUMBER($F10)),$F10<=0,NOT(ISNUMBER('Sauce Batches'!$D$80))),"",'Sauce Batches'!$D$80/$F10) | P10: =IF($G10="","",IF(SUMPRODUCT(('Sauce Batches'!$A$67:$A$78=$G10)*(ISNUMBER('Sauce Batches'!$D$67:$D$78)))>0,"This is also in the pot above - it would be paid for twice",""))
A11: Herbed Honey Garlic | B11: 175 | D11: =IF('Sauce Batches'!$B$105="","",'Sauce Batches'!$B$105) | F11: =IF(ISNUMBER($C11),$C11,IF(AND(ISNUMBER($E11),$E11>0,ISNUMBER('Sauce Batches'!$D$105)),'Sauce Batches'!$D$105/$E11,"")) | G11: Chicken wings | H11: 2 | I11: =IF($G11="","",IFERROR(VLOOKUP($G11,Lists!$A:$C,3,FALSE),"NOT ON THE LIST")) -> pc | J11: =IF(OR(NOT(ISNUMBER($F11)),NOT(ISNUMBER('Sauce Batches'!$E$106))),"",$F11*'Sauce Batches'!$E$106) | K11: =IF(OR($G11="",NOT(ISNUMBER($H11))),"",IFERROR($H11*VLOOKUP($G11,Lists!$A:$B,2,FALSE),"")) -> 22.0252 | L11: =IF(AND($J11="",$K11=""),"",N($J11)+N($K11)) -> 22.03 | M11: =IF($L11="","",$B11-$L11) -> 152.97 | N11: =IF(OR($L11="",$B11=0),"",($B11-$L11)/$B11) -> 0.87414171 | O11: =IF(OR(NOT(ISNUMBER($F11)),$F11<=0,NOT(ISNUMBER('Sauce Batches'!$D$105))),"",'Sauce Batches'!$D$105/$F11) | P11: =IF($G11="","",IF(SUMPRODUCT(('Sauce Batches'!$A$86:$A$103=$G11)*(ISNUMBER('Sauce Batches'!$D$86:$D$103)))>0,"This is also in the pot above - it would be paid for twice",""))
A12: Honey Sriracha | B12: 150 | D12: =IF('Sauce Batches'!$B$120="","",'Sauce Batches'!$B$120) | F12: =IF(ISNUMBER($C12),$C12,IF(AND(ISNUMBER($E12),$E12>0,ISNUMBER('Sauce Batches'!$D$120)),'Sauce Batches'!$D$120/$E12,"")) | I12: =IF($G12="","",IFERROR(VLOOKUP($G12,Lists!$A:$C,3,FALSE),"NOT ON THE LIST")) | J12: =IF(OR(NOT(ISNUMBER($F12)),NOT(ISNUMBER('Sauce Batches'!$E$121))),"",$F12*'Sauce Batches'!$E$121) | K12: =IF(OR($G12="",NOT(ISNUMBER($H12))),"",IFERROR($H12*VLOOKUP($G12,Lists!$A:$B,2,FALSE),"")) | L12: =IF(AND($J12="",$K12=""),"",N($J12)+N($K12)) | M12: =IF($L12="","",$B12-$L12) | N12: =IF(OR($L12="",$B12=0),"",($B12-$L12)/$B12) | O12: =IF(OR(NOT(ISNUMBER($F12)),$F12<=0,NOT(ISNUMBER('Sauce Batches'!$D$120))),"",'Sauce Batches'!$D$120/$F12) | P12: =IF($G12="","",IF(SUMPRODUCT(('Sauce Batches'!$A$111:$A$118=$G12)*(ISNUMBER('Sauce Batches'!$D$111:$D$118)))>0,"This is also in the pot above - it would be paid for twice",""))
A13: Sweet & Spicy BBQ | B13: 150 | D13: =IF('Sauce Batches'!$B$140="","",'Sauce Batches'!$B$140) | F13: =IF(ISNUMBER($C13),$C13,IF(AND(ISNUMBER($E13),$E13>0,ISNUMBER('Sauce Batches'!$D$140)),'Sauce Batches'!$D$140/$E13,"")) | I13: =IF($G13="","",IFERROR(VLOOKUP($G13,Lists!$A:$C,3,FALSE),"NOT ON THE LIST")) | J13: =IF(OR(NOT(ISNUMBER($F13)),NOT(ISNUMBER('Sauce Batches'!$E$141))),"",$F13*'Sauce Batches'!$E$141) | K13: =IF(OR($G13="",NOT(ISNUMBER($H13))),"",IFERROR($H13*VLOOKUP($G13,Lists!$A:$B,2,FALSE),"")) | L13: =IF(AND($J13="",$K13=""),"",N($J13)+N($K13)) | M13: =IF($L13="","",$B13-$L13) | N13: =IF(OR($L13="",$B13=0),"",($B13-$L13)/$B13) | O13: =IF(OR(NOT(ISNUMBER($F13)),$F13<=0,NOT(ISNUMBER('Sauce Batches'!$D$140))),"",'Sauce Batches'!$D$140/$F13) | P13: =IF($G13="","",IF(SUMPRODUCT(('Sauce Batches'!$A$126:$A$138=$G13)*(ISNUMBER('Sauce Batches'!$D$126:$D$138)))>0,"This is also in the pot above - it would be paid for twice",""))
A14: Teriyaki Wings | B14: 150 | D14: =IF('Sauce Batches'!$B$162="","",'Sauce Batches'!$B$162) | F14: =IF(ISNUMBER($C14),$C14,IF(AND(ISNUMBER($E14),$E14>0,ISNUMBER('Sauce Batches'!$D$162)),'Sauce Batches'!$D$162/$E14,"")) | I14: =IF($G14="","",IFERROR(VLOOKUP($G14,Lists!$A:$C,3,FALSE),"NOT ON THE LIST")) | J14: =IF(OR(NOT(ISNUMBER($F14)),NOT(ISNUMBER('Sauce Batches'!$E$163))),"",$F14*'Sauce Batches'!$E$163) | K14: =IF(OR($G14="",NOT(ISNUMBER($H14))),"",IFERROR($H14*VLOOKUP($G14,Lists!$A:$B,2,FALSE),"")) | L14: =IF(AND($J14="",$K14=""),"",N($J14)+N($K14)) | M14: =IF($L14="","",$B14-$L14) | N14: =IF(OR($L14="",$B14=0),"",($B14-$L14)/$B14) | O14: =IF(OR(NOT(ISNUMBER($F14)),$F14<=0,NOT(ISNUMBER('Sauce Batches'!$D$162))),"",'Sauce Batches'!$D$162/$F14) | P14: =IF($G14="","",IF(SUMPRODUCT(('Sauce Batches'!$A$146:$A$160=$G14)*(ISNUMBER('Sauce Batches'!$D$146:$D$160)))>0,"This is also in the pot above - it would be paid for twice",""))

Sheet Answers
A1: The answers - Cafe Carolina (TEST)
A2: This page fills itself in. Nothing here is typed.
A4: Prices still missing | B4: =COUNTBLANK(Ingredients!$C$8:$C$25) -> 18 | C4: out of 18 ingredients. Every dish using one is costed as free.
A5: Thinnest margin | B5: =IF(COUNT('On the Plate'!$N$8:$N$14)=0,"-",INDEX('On the Plate'!$A$8:$A$14,MATCH(MIN('On the Plate'!$N$8:$N$14),'On the Plate'!$N$8:$N$14,0))) -> - | C5: The dish to look at first.
A6: Fattest margin | B6: =IF(COUNT('On the Plate'!$N$8:$N$14)=0,"-",INDEX('On the Plate'!$A$8:$A$14,MATCH(MAX('On the Plate'!$N$8:$N$14),'On the Plate'!$N$8:$N$14,0))) -> -
A8: Dish | B8: Sells for ₱ | C8: Costs to make | D8: You keep | E8: Margin | F8: Plates per pot
A9: ='On the Plate'!$A$8 | B9: ='On the Plate'!$B$8 | C9: =IF('On the Plate'!$L$8="","",'On the Plate'!$L$8) | D9: =IF('On the Plate'!$M$8="","",'On the Plate'!$M$8) | E9: =IF('On the Plate'!$N$8="","",'On the Plate'!$N$8) | F9: =IF('On the Plate'!$O$8="","",'On the Plate'!$O$8)
A10: ='On the Plate'!$A$9 | B10: ='On the Plate'!$B$9 | C10: =IF('On the Plate'!$L$9="","",'On the Plate'!$L$9) | D10: =IF('On the Plate'!$M$9="","",'On the Plate'!$M$9) | E10: =IF('On the Plate'!$N$9="","",'On the Plate'!$N$9) | F10: =IF('On the Plate'!$O$9="","",'On the Plate'!$O$9)
A11: ='On the Plate'!$A$10 | B11: ='On the Plate'!$B$10 | C11: =IF('On the Plate'!$L$10="","",'On the Plate'!$L$10) | D11: =IF('On the Plate'!$M$10="","",'On the Plate'!$M$10) | E11: =IF('On the Plate'!$N$10="","",'On the Plate'!$N$10) | F11: =IF('On the Plate'!$O$10="","",'On the Plate'!$O$10)
A12: ='On the Plate'!$A$11 | B12: ='On the Plate'!$B$11 | C12: =IF('On the Plate'!$L$11="","",'On the Plate'!$L$11) | D12: =IF('On the Plate'!$M$11="","",'On the Plate'!$M$11) | E12: =IF('On the Plate'!$N$11="","",'On the Plate'!$N$11) | F12: =IF('On the Plate'!$O$11="","",'On the Plate'!$O$11)
A13: ='On the Plate'!$A$12 | B13: ='On the Plate'!$B$12 | C13: =IF('On the Plate'!$L$12="","",'On the Plate'!$L$12) | D13: =IF('On the Plate'!$M$12="","",'On the Plate'!$M$12) | E13: =IF('On the Plate'!$N$12="","",'On the Plate'!$N$12) | F13: =IF('On the Plate'!$O$12="","",'On the Plate'!$O$12)
A14: ='On the Plate'!$A$13 | B14: ='On the Plate'!$B$13 | C14: =IF('On the Plate'!$L$13="","",'On the Plate'!$L$13) | D14: =IF('On the Plate'!$M$13="","",'On the Plate'!$M$13) | E14: =IF('On the Plate'!$N$13="","",'On the Plate'!$N$13) | F14: =IF('On the Plate'!$O$13="","",'On the Plate'!$O$13)
A15: ='On the Plate'!$A$14 | B15: ='On the Plate'!$B$14 | C15: =IF('On the Plate'!$L$14="","",'On the Plate'!$L$14) | D15: =IF('On the Plate'!$M$14="","",'On the Plate'!$M$14) | E15: =IF('On the Plate'!$N$14="","",'On the Plate'!$N$14) | F15: =IF('On the Plate'!$O$14="","",'On the Plate'!$O$14)

Sheet Lists
A1: Ingredient | B1: Cost per recipe unit | C1: Recipe unit | E1: unit | F1: family | G1: perBase
A2: 555 Sardines Spanish Style | B2: 0.2048 | C2: g | E2: mg | F2: mass | G2: 0.001
A3: Agave Syrup | B3: 1.486 | C3: ml | E3: g | F3: mass | G3: 1
A4: Alaska Condensada | B4: 148.0734 | C4: kg | E4: kg | F4: mass | G4: 1000
A5: Alaska Evaporated Milk | B5: 0.1518 | C5: ml | E5: oz | F5: mass | G5: 28.349523
A6: All Purpose Flour | B6: 55 | C6: kg | E6: lb | F6: mass | G6: 453.59237
A7: Aluminum Foil 30cm x 8m | B7: 62 | C7: box | E7: ml | F7: volume | G7: 1
A8: Apple cider vinegar | B8: =IF(ISNUMBER(Ingredients!$I$8),Ingredients!$I$8,0) -> 0 | C8: g | E8: cl | F8: volume | G8: 10
A9: Arabica Roasted Beans Medium Dark | B9: 1100 | C9: kg | E9: l | F9: volume | G9: 1000
A10: Argentina Corned Beef | B10: 0.2115 | C10: g | E10: tsp | F10: volume | G10: 4.9289216
A11: Arla Milk Full Cream | B11: 106.35 | C11: L | E11: tbsp | F11: volume | G11: 14.786765
A12: Atchara | B12: 0.198 | C12: g | E12: cup | F12: volume | G12: 240
A13: Atsal | B13: 168 | C13: pack | E13: floz | F13: volume | G13: 29.57353
A14: Baker's Best by 2 | B14: 0.4684 | C14: g | E14: gram | F14: mass | G14: 1
A15: Balducci Penne | B15: 0.151 | C15: g | E15: grams | F15: mass | G15: 1
A16: Bambi Nachos | B16: 18.6667 | C16: box | E16: kilo | F16: mass | G16: 1000
A17: Bambi Nachos Chips | B17: 56 | C17: box | E17: kilogram | F17: mass | G17: 1000
A18: Beef Filipin | B18: 440 | C18: kg | E18: kilograms | F18: mass | G18: 1000
A19: Beef Steak | B19: 540 | C19: kg | E19: milliliter | F19: volume | G19: 1
A20: Beef Tapa | B20: 0.334 | C20: g | E20: millilitre | F20: volume | G20: 1
... A25: Biscoff Crumbs | B25: 0.7733 | C25: g | E25: litres | F25: volume | G25: 1000
A26: Biscoff Crushed | B26: 470 | C26: pc
A27: Biscoff Spread | B27: 1 | C27: g
A28: Biscoff Topping | B28: 0.7733 | C28: g
A29: Blueberry Jam | B29: 0.1267 | C29: g
A30: Blueberry Syrup | B30: 0.152 | C30: ml
A31: Breve Milk | B31: 0.0981 | C31: ml
A32: Brown sugar | B32: 0.085 | C32: g
A33: Brown Sugar | B33: 0.085 | C33: g
A34: Butter | B34: =IF(ISNUMBER(Ingredients!$I$9),Ingredients!$I$9,0) -> 0 | C34: g
A35: Calamansi | B35: 0.2295 | C35: g
A36: Campbell Cream of Mushroom B1T1 | B36: 178 | C36: can
A37: Caramel Sauce | B37: 0.5 | C37: ml
A38: Cayenne pepper | B38: =IF(ISNUMBER(Ingredients!$I$10),Ingredients!$I$10,0) -> 0 | C38: g
A39: CDO Chicken Ham | B39: 0.4216 | C39: g
A40: CDO Hamburger Patty | B40: 37.75 | C40: pc
A41: CDO Highlands Premium | B41: 246 | C41: can
A42: Century Tuna Chuncks in Veg oil | B42: 0.2449 | C42: g
A43: Chicken Breast | B43: 250 | C43: kg
A44: Chicken Knoor Cubes | B44: 0.609 | C44: g
...
