Workbook

Sheet Recipes
A1: Product Name* | B1: Ingredient Name* | C1: Quantity* | D1: Unit | E1: Category | F1: Made or Bought | G1: Cost per Unit (₱) | H1: Line Cost (₱) | I1: Priced?
A2: Americano ( Hot ) | B2: Coffee Beans | C2: 17 | D2: g | E2: Black and White - Hot | F2: Bought | G2: 1.1 | H2: =IF(OR(NOT(ISNUMBER($C2)),NOT(ISNUMBER($G2))),"",$C2*$G2) -> 18.7 | I2: Yes
A3: Americano ( Hot ) | B3: Hot Cup 12oz | C3: 1 | D3: pc | E3: Black and White - Hot | F3: Bought | G3: 5 | H3: =IF(OR(NOT(ISNUMBER($C3)),NOT(ISNUMBER($G3))),"",$C3*$G3) -> 5 | I3: Yes
A4: Americano ( Hot ) | B4: Hot Lid | C4: 1 | D4: pc | E4: Black and White - Hot | F4: Bought | G4: 1.6 | H4: =IF(OR(NOT(ISNUMBER($C4)),NOT(ISNUMBER($G4))),"",$C4*$G4) -> 1.6 | I4: Yes
A5: Americano ( Hot ) | B5: Water | C5: 300 | D5: ml | E5: Black and White - Hot | F5: Bought | G5: 0.002 | H5: =IF(OR(NOT(ISNUMBER($C5)),NOT(ISNUMBER($G5))),"",$C5*$G5) -> 0.6 | I5: Yes
A6: Americano ( Iced ) | B6: Coffee Beans | C6: 17 | D6: g | E6: Black and White - Iced | F6: Bought | G6: 1.1 | H6: =IF(OR(NOT(ISNUMBER($C6)),NOT(ISNUMBER($G6))),"",$C6*$G6) -> 18.7 | I6: Yes
A7: Americano ( Iced ) | B7: Cold Cup 16oz | C7: 1 | D7: pc | E7: Black and White - Iced | F7: Bought | G7: 3.64 | H7: =IF(OR(NOT(ISNUMBER($C7)),NOT(ISNUMBER($G7))),"",$C7*$G7) -> 3.64 | I7: Yes
A8: Americano ( Iced ) | B8: Ice | C8: 300 | D8: g | E8: Black and White - Iced | F8: Bought | G8: 0.0015 | H8: =IF(OR(NOT(ISNUMBER($C8)),NOT(ISNUMBER($G8))),"",$C8*$G8) -> 0.45 | I8: Yes
A9: Americano ( Iced ) | B9: Strawless Lid ( Cold ) | C9: 1 | D9: pc | E9: Black and White - Iced | F9: Bought | G9: 1.6429 | H9: =IF(OR(NOT(ISNUMBER($C9)),NOT(ISNUMBER($G9))),"",$C9*$G9) -> 1.6429 | I9: Yes
A10: Americano ( Iced ) | B10: Water | C10: 150 | D10: ml | E10: Black and White - Iced | F10: Bought | G10: 0.002 | H10: =IF(OR(NOT(ISNUMBER($C10)),NOT(ISNUMBER($G10))),"",$C10*$G10) -> 0.3 | I10: Yes
A11: Berry Carolina | B11: Cold Cup 16oz | C11: 1 | D11: pc | E11: Yogurt Series | F11: Bought | G11: 3.64 | H11: =IF(OR(NOT(ISNUMBER($C11)),NOT(ISNUMBER($G11))),"",$C11*$G11) -> 3.64 | I11: Yes
A12: Berry Carolina | B12: Emborg Fresh Milk | C12: 150 | D12: ml | E12: Yogurt Series | F12: Bought | G12: 0.09 | H12: =IF(OR(NOT(ISNUMBER($C12)),NOT(ISNUMBER($G12))),"",$C12*$G12) -> 13.5 | I12: Yes
A13: Berry Carolina | B13: Ice | C13: 300 | D13: g | E13: Yogurt Series | F13: Bought | G13: 0.0015 | H13: =IF(OR(NOT(ISNUMBER($C13)),NOT(ISNUMBER($G13))),"",$C13*$G13) -> 0.45 | I13: Yes
... A59: Blueberry Yogurt | B59: Yogurt | C59: 40 | D59: ml | E59: Yogurt Series | F59: Bought | G59: 0.34 | H59: =IF(OR(NOT(ISNUMBER($C59)),NOT(ISNUMBER($G59))),"",$C59*$G59) -> 13.6 | I59: Yes
A60: Buffalo Wings | B60: Butter | C60: 0.7 | D60: g | E60: Wings & Chicken | F60: Bought | H60: =IF(OR(NOT(ISNUMBER($C60)),NOT(ISNUMBER($G60))),"",$C60*$G60) | I60: No price yet
A61: Buffalo Wings | B61: Cayenne pepper | C61: 1 | D61: g | E61: Wings & Chicken | F61: Bought | H61: =IF(OR(NOT(ISNUMBER($C61)),NOT(ISNUMBER($G61))),"",$C61*$G61) | I61: No price yet
A62: Buffalo Wings | B62: Chicken wings | C62: 2 | D62: pc | E62: Wings & Chicken | F62: Bought | G62: 11.0126 | H62: =IF(OR(NOT(ISNUMBER($C62)),NOT(ISNUMBER($G62))),"",$C62*$G62) -> 22.0252 | I62: Yes
A63: Buffalo Wings | B63: Chili powder | C63: 1 | D63: g | E63: Wings & Chicken | F63: Bought | G63: 2.864 | H63: =IF(OR(NOT(ISNUMBER($C63)),NOT(ISNUMBER($G63))),"",$C63*$G63) -> 2.864 | I63: Yes
A64: Buffalo Wings | B64: Flour | C64: 20 | D64: g | E64: Wings & Chicken | F64: Bought | H64: =IF(OR(NOT(ISNUMBER($C64)),NOT(ISNUMBER($G64))),"",$C64*$G64) | I64: No price yet
A65: Buffalo Wings | B65: Ground Black Pepper | C65: 1 | D65: g | E65: Wings & Chicken | F65: Bought | G65: 1.1667 | H65: =IF(OR(NOT(ISNUMBER($C65)),NOT(ISNUMBER($G65))),"",$C65*$G65) -> 1.1667 | I65: Yes
A66: Buffalo Wings | B66: Paprika | C66: 1 | D66: g | E66: Wings & Chicken | F66: Bought | H66: =IF(OR(NOT(ISNUMBER($C66)),NOT(ISNUMBER($G66))),"",$C66*$G66) | I66: No price yet
A67: Buffalo Wings | B67: Salt | C67: 0.8 | D67: g | E67: Wings & Chicken | F67: Bought | H67: =IF(OR(NOT(ISNUMBER($C67)),NOT(ISNUMBER($G67))),"",$C67*$G67) | I67: No price yet
A68: Buffalo Wings | B68: Sesame Seed | C68: 5 | D68: g | E68: Wings & Chicken | F68: Bought | G68: 0.395 | H68: =IF(OR(NOT(ISNUMBER($C68)),NOT(ISNUMBER($G68))),"",$C68*$G68) -> 1.975 | I68: Yes
A69: Buffalo Wings | B69: Sriracha | C69: 15 | D69: g | E69: Wings & Chicken | F69: Bought | H69: =IF(OR(NOT(ISNUMBER($C69)),NOT(ISNUMBER($G69))),"",$C69*$G69) | I69: No price yet
A70: Buffalo Wings | B70: Sugar | C70: 5 | D70: g | E70: Wings & Chicken | F70: Bought | G70: 0.09 | H70: =IF(OR(NOT(ISNUMBER($C70)),NOT(ISNUMBER($G70))),"",$C70*$G70) -> 0.45 | I70: Yes
A71: Café Latte ( Hot ) | B71: Coffee Beans | C71: 17 | D71: g | E71: Black and White - Hot | F71: Bought | G71: 1.1 | H71: =IF(OR(NOT(ISNUMBER($C71)),NOT(ISNUMBER($G71))),"",$C71*$G71) -> 18.7 | I71: Yes
A72: Café Latte ( Hot ) | B72: Emborg Fresh Milk | C72: 200 | D72: ml | E72: Black and White - Hot | F72: Bought | G72: 0.09 | H72: =IF(OR(NOT(ISNUMBER($C72)),NOT(ISNUMBER($G72))),"",$C72*$G72) -> 18 | I72: Yes
A73: Café Latte ( Hot ) | B73: Hot Cup 12oz | C73: 1 | D73: pc | E73: Black and White - Hot | F73: Bought | G73: 5 | H73: =IF(OR(NOT(ISNUMBER($C73)),NOT(ISNUMBER($G73))),"",$C73*$G73) -> 5 | I73: Yes
A74: Café Latte ( Hot ) | B74: Hot Lid | C74: 1 | D74: pc | E74: Black and White - Hot | F74: Bought | G74: 1.6 | H74: =IF(OR(NOT(ISNUMBER($C74)),NOT(ISNUMBER($G74))),"",$C74*$G74) -> 1.6 | I74: Yes
A75: Café Latte ( Iced ) | B75: Coffee Beans | C75: 17 | D75: g | E75: Black and White - Iced | F75: Bought | G75: 1.1 | H75: =IF(OR(NOT(ISNUMBER($C75)),NOT(ISNUMBER($G75))),"",$C75*$G75) -> 18.7 | I75: Yes
A76: Café Latte ( Iced ) | B76: Cold Cup 16oz | C76: 1 | D76: pc | E76: Black and White - Iced | F76: Bought | G76: 3.64 | H76: =IF(OR(NOT(ISNUMBER($C76)),NOT(ISNUMBER($G76))),"",$C76*$G76) -> 3.64 | I76: Yes
A77: Café Latte ( Iced ) | B77: Emborg Fresh Milk | C77: 150 | D77: ml | E77: Black and White - Iced | F77: Bought | G77: 0.09 | H77: =IF(OR(NOT(ISNUMBER($C77)),NOT(ISNUMBER($G77))),"",$C77*$G77) -> 13.5 | I77: Yes
A78: Café Latte ( Iced ) | B78: Ice | C78: 300 | D78: g | E78: Black and White - Iced | F78: Bought | G78: 0.0015 | H78: =IF(OR(NOT(ISNUMBER($C78)),NOT(ISNUMBER($G78))),"",$C78*$G78) -> 0.45 | I78: Yes
A79: Café Latte ( Iced ) | B79: Strawless Lid ( Cold ) | C79: 1 | D79: pc | E79: Black and White - Iced | F79: Bought | G79: 1.6429 | H79: =IF(OR(NOT(ISNUMBER($C79)),NOT(ISNUMBER($G79))),"",$C79*$G79) -> 1.6429 | I79: Yes
A80: Café Mocha ( Hot ) | B80: Coffee Beans | C80: 17 | D80: g | E80: House Special - Hot | F80: Bought | G80: 1.1 | H80: =IF(OR(NOT(ISNUMBER($C80)),NOT(ISNUMBER($G80))),"",$C80*$G80) -> 18.7 | I80: Yes
A81: Café Mocha ( Hot ) | B81: DaVinci Gourmet Chocolate Sauce | C81: 30 | D81: ml | E81: House Special - Hot | F81: Bought | G81: 0.6085 | H81: =IF(OR(NOT(ISNUMBER($C81)),NOT(ISNUMBER($G81))),"",$C81*$G81) -> 18.255 | I81: Yes
... A144: Flat White ( Hot ) | B144: Hot Lid | C144: 1 | D144: pc | E144: Black and White - Hot | F144: Bought | G144: 1.6 | H144: =IF(OR(NOT(ISNUMBER($C144)),NOT(ISNUMBER($G144))),"",$C144*$G144) -> 1.6 | I144: Yes
A145: Garlic Chicken | B145: Butter | C145: 2.4 | D145: g | E145: Wings & Chicken | F145: Bought | H145: =IF(OR(NOT(ISNUMBER($C145)),NOT(ISNUMBER($G145))),"",$C145*$G145) | I145: No price yet
A146: Garlic Chicken | B146: Garlic | C146: 2.5 | D146: g | E146: Wings & Chicken | F146: Bought | G146: 0.112 | H146: =IF(OR(NOT(ISNUMBER($C146)),NOT(ISNUMBER($G146))),"",$C146*$G146) -> 0.28 | I146: Yes
A147: Garlic Chicken | B147: Knorr Liquid Seasoning | C147: 40 | D147: ml | E147: Wings & Chicken | F147: Bought | G147: 0.3395 | H147: =IF(OR(NOT(ISNUMBER($C147)),NOT(ISNUMBER($G147))),"",$C147*$G147) -> 13.58 | I147: Yes
...

Sheet Dish Costs
A1: Category | B1: Product Name | C1: Sells For (₱) | D1: Cost to Make (₱) | E1: Margin (₱) | F1: Margin % | G1: Recipe Lines | H1: Lines With No Price | I1: Costing Complete?
A2: Black and White - Hot | B2: Americano ( Hot ) | C2: 80 | D2: =SUMPRODUCT((Recipes!$A$2:$A$480=$B2)*IF(ISNUMBER(Recipes!$H$2:$H$480),Recipes!$H$2:$H$480,0)) -> 25.9 | E2: =IF($D2="","",$C2-$D2) -> 54.1 | F2: =IF(OR($I2<>"Yes",$C2<=0),"",($C2-$D2)/$C2) -> 0.67625 | G2: =SUMPRODUCT((Recipes!$A$2:$A$480=$B2)*1) -> 4 | H2: =SUMPRODUCT((Recipes!$A$2:$A$480=$B2)*(Recipes!$I$2:$I$480="No price yet")) -> 0 | I2: =IF($H2>0,"No","Yes") -> Yes
A3: Black and White - Iced | B3: Americano ( Iced ) | C3: 100 | D3: =SUMPRODUCT((Recipes!$A$2:$A$480=$B3)*IF(ISNUMBER(Recipes!$H$2:$H$480),Recipes!$H$2:$H$480,0)) -> 24.73 | E3: =IF($D3="","",$C3-$D3) -> 75.27 | F3: =IF(OR($I3<>"Yes",$C3<=0),"",($C3-$D3)/$C3) -> 0.752671 | G3: =SUMPRODUCT((Recipes!$A$2:$A$480=$B3)*1) -> 5 | H3: =SUMPRODUCT((Recipes!$A$2:$A$480=$B3)*(Recipes!$I$2:$I$480="No price yet")) -> 0 | I3: =IF($H3>0,"No","Yes") -> Yes
A4: Yogurt Series | B4: Berry Carolina | C4: 149 | D4: =SUMPRODUCT((Recipes!$A$2:$A$480=$B4)*IF(ISNUMBER(Recipes!$H$2:$H$480),Recipes!$H$2:$H$480,0)) -> 47.84 | E4: =IF($D4="","",$C4-$D4) -> 101.16 | F4: =IF(OR($I4<>"Yes",$C4<=0),"",($C4-$D4)/$C4) -> 0.678893 | G4: =SUMPRODUCT((Recipes!$A$2:$A$480=$B4)*1) -> 7 | H4: =SUMPRODUCT((Recipes!$A$2:$A$480=$B4)*(Recipes!$I$2:$I$480="No price yet")) -> 0 | I4: =IF($H4>0,"No","Yes") -> Yes
A5: Yogurt Series | B5: Biscoff Carolina | C5: 159 | D5: =SUMPRODUCT((Recipes!$A$2:$A$480=$B5)*IF(ISNUMBER(Recipes!$H$2:$H$480),Recipes!$H$2:$H$480,0)) -> 69.43 | E5: =IF($D5="","",$C5-$D5) -> 89.57 | F5: =IF(OR($I5<>"Yes",$C5<=0),"",($C5-$D5)/$C5) -> 0.563354 | G5: =SUMPRODUCT((Recipes!$A$2:$A$480=$B5)*1) -> 9 | H5: =SUMPRODUCT((Recipes!$A$2:$A$480=$B5)*(Recipes!$I$2:$I$480="No price yet")) -> 0 | I5: =IF($H5>0,"No","Yes") -> Yes
A6: Frappe - Milk Based | B6: Biscoff Frappe | C6: 179 | D6: =SUMPRODUCT((Recipes!$A$2:$A$480=$B6)*IF(ISNUMBER(Recipes!$H$2:$H$480),Recipes!$H$2:$H$480,0)) -> 72.51 | E6: =IF($D6="","",$C6-$D6) -> 106.49 | F6: =IF(OR($I6<>"Yes",$C6<=0),"",($C6-$D6)/$C6) -> 0.594919 | G6: =SUMPRODUCT((Recipes!$A$2:$A$480=$B6)*1) -> 10 | H6: =SUMPRODUCT((Recipes!$A$2:$A$480=$B6)*(Recipes!$I$2:$I$480="No price yet")) -> 0 | I6: =IF($H6>0,"No","Yes") -> Yes
A7: Frappe - Milk Based | B7: Blueberries & Cream | C7: 149 | D7: =SUMPRODUCT((Recipes!$A$2:$A$480=$B7)*IF(ISNUMBER(Recipes!$H$2:$H$480),Recipes!$H$2:$H$480,0)) -> 48.49 | E7: =IF($D7="","",$C7-$D7) -> 100.51 | F7: =IF(OR($I7<>"Yes",$C7<=0),"",($C7-$D7)/$C7) -> 0.674581 | G7: =SUMPRODUCT((Recipes!$A$2:$A$480=$B7)*1) -> 8 | H7: =SUMPRODUCT((Recipes!$A$2:$A$480=$B7)*(Recipes!$I$2:$I$480="No price yet")) -> 0 | I7: =IF($H7>0,"No","Yes") -> Yes
A8: Soda | B8: Blueberry Soda | C8: 70 | D8: =SUMPRODUCT((Recipes!$A$2:$A$480=$B8)*IF(ISNUMBER(Recipes!$H$2:$H$480),Recipes!$H$2:$H$480,0)) -> 26.76 | E8: =IF($D8="","",$C8-$D8) -> 43.24 | F8: =IF(OR($I8<>"Yes",$C8<=0),"",($C8-$D8)/$C8) -> 0.617644 | G8: =SUMPRODUCT((Recipes!$A$2:$A$480=$B8)*1) -> 8 | H8: =SUMPRODUCT((Recipes!$A$2:$A$480=$B8)*(Recipes!$I$2:$I$480="No price yet")) -> 0 | I8: =IF($H8>0,"No","Yes") -> Yes
A9: Yogurt Series | B9: Blueberry Yogurt | C9: 139 | D9: =SUMPRODUCT((Recipes!$A$2:$A$480=$B9)*IF(ISNUMBER(Recipes!$H$2:$H$480),Recipes!$H$2:$H$480,0)) -> 36.98 | E9: =IF($D9="","",$C9-$D9) -> 102.02 | F9: =IF(OR($I9<>"Yes",$C9<=0),"",($C9-$D9)/$C9) -> 0.733965 | G9: =SUMPRODUCT((Recipes!$A$2:$A$480=$B9)*1) -> 7 | H9: =SUMPRODUCT((Recipes!$A$2:$A$480=$B9)*(Recipes!$I$2:$I$480="No price yet")) -> 0 | I9: =IF($H9>0,"No","Yes") -> Yes
A10: Wings & Chicken | B10: Buffalo Wings | C10: 150 | D10: =SUMPRODUCT((Recipes!$A$2:$A$480=$B10)*IF(ISNUMBER(Recipes!$H$2:$H$480),Recipes!$H$2:$H$480,0)) -> 28.48 | E10: =IF($D10="","",$C10-$D10) -> 121.52 | F10: =IF(OR($I10<>"Yes",$C10<=0),"",($C10-$D10)/$C10) | G10: =SUMPRODUCT((Recipes!$A$2:$A$480=$B10)*1) -> 11 | H10: =SUMPRODUCT((Recipes!$A$2:$A$480=$B10)*(Recipes!$I$2:$I$480="No price yet")) -> 6 | I10: =IF($H10>0,"No","Yes") -> No
A11: Black and White - Hot | B11: Café Latte ( Hot ) | C11: 120 | D11: =SUMPRODUCT((Recipes!$A$2:$A$480=$B11)*IF(ISNUMBER(Recipes!$H$2:$H$480),Recipes!$H$2:$H$480,0)) -> 43.3 | E11: =IF($D11="","",$C11-$D11) -> 76.7 | F11: =IF(OR($I11<>"Yes",$C11<=0),"",($C11-$D11)/$C11) -> 0.639167 | G11: =SUMPRODUCT((Recipes!$A$2:$A$480=$B11)*1) -> 4 | H11: =SUMPRODUCT((Recipes!$A$2:$A$480=$B11)*(Recipes!$I$2:$I$480="No price yet")) -> 0 | I11: =IF($H11>0,"No","Yes") -> Yes
A12: Black and White - Iced | B12: Café Latte ( Iced ) | C12: 120 | D12: =SUMPRODUCT((Recipes!$A$2:$A$480=$B12)*IF(ISNUMBER(Recipes!$H$2:$H$480),Recipes!$H$2:$H$480,0)) -> 37.93 | E12: =IF($D12="","",$C12-$D12) -> 82.07 | F12: =IF(OR($I12<>"Yes",$C12<=0),"",($C12-$D12)/$C12) -> 0.683893 | G12: =SUMPRODUCT((Recipes!$A$2:$A$480=$B12)*1) -> 5 | H12: =SUMPRODUCT((Recipes!$A$2:$A$480=$B12)*(Recipes!$I$2:$I$480="No price yet")) -> 0 | I12: =IF($H12>0,"No","Yes") -> Yes
A13: House Special - Hot | B13: Café Mocha ( Hot ) | C13: 130 | D13: =SUMPRODUCT((Recipes!$A$2:$A$480=$B13)*IF(ISNUMBER(Recipes!$H$2:$H$480),Recipes!$H$2:$H$480,0)) -> 61.56 | E13: =IF($D13="","",$C13-$D13) -> 68.44 | F13: =IF(OR($I13<>"Yes",$C13<=0),"",($C13-$D13)/$C13) -> 0.5265 | G13: =SUMPRODUCT((Recipes!$A$2:$A$480=$B13)*1) -> 5 | H13: =SUMPRODUCT((Recipes!$A$2:$A$480=$B13)*(Recipes!$I$2:$I$480="No price yet")) -> 0 | I13: =IF($H13>0,"No","Yes") -> Yes
... A75: Signature Coffee - Iced | B75: White Mocha Latte ( Iced ) | C75: 169 | D75: =SUMPRODUCT((Recipes!$A$2:$A$480=$B75)*IF(ISNUMBER(Recipes!$H$2:$H$480),Recipes!$H$2:$H$480,0)) -> 39.15 | E75: =IF($D75="","",$C75-$D75) -> 129.85 | F75: =IF(OR($I75<>"Yes",$C75<=0),"",($C75-$D75)/$C75) -> 0.768356 | G75: =SUMPRODUCT((Recipes!$A$2:$A$480=$B75)*1) -> 5 | H75: =SUMPRODUCT((Recipes!$A$2:$A$480=$B75)*(Recipes!$I$2:$I$480="No price yet")) -> 0 | I75: =IF($H75>0,"No","Yes") -> Yes

Sheet Notes
A1: Your recipes, costed
A3: 479 recipe lines across 74 products, exported 2026-09-02.
A4: 7 products cannot be costed yet because 17 ingredients have no price. Their margin is left blank rather than reported as if the missing ingredient were free.
A5: No price yet: Butter, Cayenne pepper, Flour, Paprika, Salt, Sriracha, Honey, Parsley, Apple cider vinegar, Dried rosemary, Dried thyme, Pepper, Soy sauce, Garlic powder, Ketchup, Oil, Ginger
A7: To pivot it
A8: Click any cell on Recipes or Dish Costs, then Insert > PivotTable. The range is already a named table (RecipeLines and DishCosts), so Excel fills the source in for you.
A9: Pivot Recipes to ask where the money goes — Line Cost by Ingredient, or by Category. Pivot Dish Costs to ask which dishes earn — Margin % by Product. Keep them apart: a selling price summed once per ingredient is eleven times too big, which is why it is not on the Recipes sheet.
A11: To change something
A12: Edit Quantity on the Recipes sheet and upload this file back at Settings > Import > Recipes. Only the first four columns are read; everything after them is ignored on the way in.
A13: Do NOT edit a Product Name or an Ingredient Name. Both are matched by name, so an edited one either fails to find its target or attaches the line to something else.
A14: Adding a line to an existing dish works — type it under the last row. A brand-new dish, or a brand-new ingredient, has to exist first: add it with the Products or Ingredients template, or use the Setup Pack, which loads Products, then Ingredients, then Recipes in one upload.
A15: Deleting a row here does NOT delete the recipe line. The import only ever adds or updates; remove a line in the app instead.
... A18: It is what the ingredient costs in Clerque right now. Recording a delivery recalculates it as a weighted average of what you actually paid, so export again after a delivery rather than trusting an old file.
